Workbook
Name valuevx: 42.314159

Sheet Existing
A1: HC | B1: Existing | D1: NBL | E1: Sathish feedback | F1: Domain | G1: Target | K1: What IF
B2: ON | C2: OFF | G2: ON | H2: OFF | I2: Total | K2: ON | L2: OFF | M2: Total
A3: =SUM(B3:C3) -> 10 | B3: 2 | C3: 8 | E3: 2 ON and 8 OFF | F3: Enrollment | G3: 1 | H3: 9 | I3: =SUM(G3,H3) -> 10 | K3: 1 | L3: 9 | M3: =SUM(K3,L3) -> 10 | N3: Daniel
A4: =SUM(B4:C4) -> 10 | B4: 2 | C4: 8 | E4: Optimizable to 2 ON and 8 OFF | F4: Provider | G4: 1 | H4: 9 | I4: =SUM(G4,H4) -> 10 | K4: 1 | L4: 9 | M4: =SUM(K4,L4) -> 10 | N4: Kalai
A5: =SUM(B5:C5) -> 10 | B5: 2 | C5: 8 | F5: Claims | G5: 1 | H5: 9 | I5: =SUM(G5,H5) -> 10 | K5: 1 | L5: 9 | M5: =SUM(K5,L5) -> 10
A6: =SUM(B6:C6) -> 10 | B6: 2 | C6: 8 | E6: have 2 buffers | F6: Digital | G6: 1 | H6: 9 | I6: =SUM(G6,H6) -> 10 | K6: 1 | L6: 9 | M6: =SUM(K6,L6) -> 10
A7: =SUM(B7:C7) -> 7 | B7: 2 | C7: 5 | E7: 1 ON and 6 OFF | F7: MyLife | G7: 1 | H7: 6 | I7: =SUM(G7,H7) -> 7 | K7: 1 | L7: 6 | M7: =SUM(K7,L7) -> 7
A8: =SUM(B8:C8) -> 13 | B8: 2 | C8: 11 | E8: Optimize Asc | F8: EDI | G8: 1 | H8: 9 | I8: =SUM(G8,H8) -> 10 | K8: 1 | L8: 9 | M8: =SUM(K8,L8) -> 10 | N8: jegadish
A9: =SUM(B9:C9) -> 10 | B9: 2 | C9: 8 | E9: Downsizing 3 offshore | F9: Encounters | G9: 1 | H9: 9 | I9: =SUM(G9,H9) -> 10 | K9: 1 | L9: 9 | M9: =SUM(K9,L9) -> 10
A10: =SUM(B10:C10) -> 4 | B10: 1 | C10: 3 | E10: 2 modules - Optimize Offshore | F10: SAP Finance | G10: 1 | H10: 4 | I10: =SUM(G10,H10) -> 5 | K10: 1 | L10: 4 | M10: =SUM(K10,L10) -> 5
A11: =SUM(B11:C11) -> 3 | B11: 1 | C11: 2 | E11: Optimize Asc | F11: Clinical - Clin Auto | G11: 1 | H11: 3 | I11: =SUM(G11,H11) -> 4 | K11: 1 | L11: 3 | M11: =SUM(K11,L11) -> 4 | N11: Bhavani
A12: =SUM(B12:C12) -> 13 | B12: 2 | C12: 11 | F12: Clinical - UM/CM | G12: 1 | H12: 9 | I12: =SUM(G12,H12) -> 10 | K12: 1 | L12: 9 | M12: =SUM(K12,L12) -> 10
F13: SharedServices | I13: =SUM(G13,H13) -> 0 | M13: =SUM(K13,L13) -> 0
A14: =SUM(B14:C14) -> 4 | B14: 1 | C14: 3 | E14: 1 Solid Automation 3 PM EST coverage | F14: CrossProduct | G14: 0 | H14: 3 | I14: =SUM(G14,H14) -> 3 | K14: 0 | L14: 3 | M14: =SUM(K14,L14) -> 3
A15: =SUM(B15:C15) -> 2 | C15: 2 | D15: 1 | F15: AI Testing (QE for AI) | G15: 0 | H15: 2 | I15: =SUM(G15,H15) -> 2 | K15: 0 | L15: 2 | M15: =SUM(K15,L15) -> 2
A16: =SUM(B16:C16) -> 4 | B16: 1 | C16: 3 | D16: 3 | E16: Recommended 1 ON | F16: GenAI Team{Foundational Build) | G16: 0 | H16: 4 | I16: =SUM(G16,H16) -> 4 | K16: 0 | L16: 4 | M16: =SUM(K16,L16) -> 4
A17: =SUM(B17:C17) -> 4 | B17: 1 | C17: 3 | F17: TDM | G17: 1 | H17: 3 | I17: =SUM(G17,H17) -> 4 | K17: 1 | L17: 3 | M17: =SUM(K17,L17) -> 4 | N17: Ranjeeth
A18: =SUM(B18:C18) -> 2 | B18: 1 | C18: 1 | F18: Platform Enablement TestingTools / Tools Admin | G18: 0 | H18: 1 | I18: =SUM(G18,H18) -> 1 | K18: 0 | L18: 1 | M18: =SUM(K18,L18) -> 1
A19: TOTAL | B19: =SUM(B3:B18) -> 22 | C19: =SUM(C3:C18) -> 84 | D19: =SUM(D3:D18) -> 4 | F19: Total | G19: =SUM(G3:G18) -> 11 | H19: =SUM(H3:H18) -> 89 | I19: =SUM(G19,H19) -> 100 | K19: =SUM(K3:K18) -> 11 | L19: =SUM(L3:L18) -> 89 | M19: =SUM(K19,L19) -> 100
C20: =SUM(B19:C19) -> 106
H21: Target | I21: 46310
B22: 11 | C22: 89 | I22: 46327
I23: 46294 | J23: Initiate ID creation
I24: 46295 | J24: All Leads Selections
I25: 46297 | J25: Care Source ID created
I26: 46304 | J26: 50 % team to be onboarded
M27: Megala
M28: Md Naaeem
M29: Danesh

Sheet Hiring Tracker
A1: First Name | B1: Last Name | C1: Location | D1: Date of Joining | E1: Domain | F1: Level | G1: Status | H1: Location | I1: Healthcare | J1: Automation
A2: Radhakrishnan | B2: Kumaravel | C2: Offshore | D2: 46307 | G2: Ascendion Pipeline | O2: Healthcare SME
A3: Bhargavi | B3: Nichenamatla | C3: Offshore | D3: 46310 | G3: Ascendion Pipeline | O3: AI Lead
A4: Renganathan | B4: R | C4: Offshore | D4: 46310 | G4: Ascendion Pipeline | O4: AI Builders
A5: Rahul | B5: Macherla | C5: Offshore | D5: 46314 | G5: Ascendion Pipeline | O5: AI Builders
A6: Abhishek | B6: Gowda | C6: Offshore | D6: 46318 | G6: Ascendion Pipeline | O6: AI Builders
A7: Ramya | B7: Bhat | C7: Offshore | D7: 46323 | G7: Ascendion Pipeline
A8: Karthick | B8: Ravichandran | C8: Offshore | D8: 46323 | G8: Ascendion Pipeline
A9: Jagan | B9: S | C9: Offshore | D9: 46335 | G9: Ascendion Pipeline
A10: Mohammed | B10: Irfan Khan J | C10: Offshore | D10: 46335 | G10: Ascendion Pipeline
A11: Harisha | B11: P | C11: Offshore | D11: 46338 | G11: Ascendion Pipeline
A12: Geentanjali | B12: S | C12: Offshore | D12: 46344 | G12: Ascendion Pipeline
A13: Meenakshi Sundaram | B13: Murugappa | C13: Offshore | D13: 46349 | G13: Ascendion Pipeline
A14: Ashok Kumar | B14: S | C14: Offshore | D14: 46352 | G14: Ascendion Pipeline
A15: Arunkumar | B15: Charles | C15: Onsite | D15: 46204 | E15: Plan Preview | G15: Existing
A16: Ganesha | B16: SR | C16: Offshore | D16: 46204 | E16: EDI | G16: Existing
A17: Sowjanya | B17: Prathi | C17: Offshore | D17: 46204 | E17: EDI | G17: Existing
A18: Jegadhish | B18: Saravana Bavan | C18: Onsite | D18: 46113 | E18: ='Team Roster'!$A$8 -> EDI | G18: Existing
A19: Ragamayi | B19: Galla | C19: Onsite | D19: 46244 | E19: EDI | G19: Existing
A20: Bhavani | B20: Jaganathan Radhakrishnan | C20: Onsite | D20: 46113 | E20: Clinical | G20: Existing
A21: Gopala Swamy | B21: Kanda | C21: Offshore | D21: 46113 | E21: EDI | G21: Existing
A22: Gomathi | B22: Manogaran | C22: Offshore | D22: 46113 | E22: Clinical | G22: Existing
A23: Vanitha | B23: Thangathurai | C23: Offshore | D23: 46113 | E23: EDI | G23: Existing
A24: Nithyanantham | B24: V | C24: Offshore | D24: 46113 | E24: ='Team Roster'!$A$4 -> Claims | G24: Existing
A25: Nalluri | B25: Manohar | C25: Offshore | D25: 46204 | E25: EDI | G25: Existing
A26: Vijaya | B26: Vemula | C26: Offshore | D26: 46113 | E26: EDI | G26: Existing
A27: Berin | B27: Jeio K C | C27: Offshore | D27: 46113 | E27: EDI | G27: Existing
A28: Dillikumar | B28: R | C28: Offshore | D28: 46155 | E28: Encounters | G28: Existing
A29: Manikandan | B29: Balasubramani | C29: Offshore | D29: 46121 | E29: ='Team Roster'!$A$3 -> Provider | G29: Existing
A30: Bhavya | B30: BC | C30: Offshore | D30: 46155 | E30: Encounters | G30: Existing
A31: Selva Ganesh | B31: Murugadoss | C31: Offshore | D31: 46113 | E31: Clinical | G31: Existing
A32: Alaguraja | B32: Muthu | C32: Offshore | D32: 46113 | E32: EDI | G32: Existing
A33: Vaitheeswaran | B33: Sundararaj | C33: Onsite | D33: 46113 | E33: ='Team Roster'!$A$3 -> Provider | G33: Existing
A34: Balaji | B34: Selvaraj | C34: Offshore | D34: 46204 | E34: Clinical | G34: Existing
A35: Abhishek | B35: Gadwal R K | C35: Onsite | D35: 46146 | E35: EDI | G35: Existing
A36: Chandrakanth | B36: Pitchika | C36: Offshore | D36: 46113 | E36: EDI | G36: Existing
A37: Ranjeet | B37: Kasetty | C37: Onsite | D37: 46295 | E37: TDM | G37: Existing
A38: Hrishikesh | B38: Rode | C38: Offshore | D38: 46295 | E38: TDM | G38: Existing
A39: Digital tester1 | C39: Offshore | D39: TBD | E39: Digital | G39: Identifying
A40: Digital tester2 | C40: Offshore | D40: TBD | E40: Digital | G40: Identifying
...

Sheet HiringTracker-Infosys
A1: First Name | B1: Last Name | C1: Location | D1: Date of Joining | E1: Domain | F1: Level | G1: Status | H1: Location | I1: Healthcare | J1: Automation
A2: Test | B2: Test | C2: Onsite | D2: 46327 | E2: CXP | F2: Level 4 | G2: KT Ready

Sheet KT-Status
A1: KT SUMMARY STATUS | N1: SIGN OFF
A2: # | B2: Application | C2: RAG Status | D2: KT Completion-Target | E2: KT Completion - Actual | F2: KT Start Date | G2: Understanding Doc | H2: Shadow | I2: Reverse-KT | J2: Reverse-Shadow | K2: Steady State | L2: Owner | N2: Confidence level from QE Managers | O2: Confidence level from EQE(vendor)
A3: 1 | B3: Enrollment | C3: Green | D3: =IF(F3>TODAY(),0%,NETWORKDAYS(F3,TODAY())*R3%) -> 0.33333333 | E3: 0.08 | F3: 46307 | G3: In Progress | H3: 46323 | I3: 46314 | J3: 46330 | K3: 46337 | L3: Ascendion | Q3: =NETWORKDAYS(F3,H3-1) -> 12 | R3: =100/Q3 -> 8.3333333
A4: 2 | B4: Provider | D4: =IF(F4>TODAY(),0%,NETWORKDAYS(F4,TODAY())*R4%) -> 0.33333333 | E4: 0.08 | F4: 46307 | G4: In Progress | H4: 46323 | I4: 46314 | J4: 46330 | K4: 46337 | L4: Ascendion | Q4: =NETWORKDAYS(F4,H4-1) -> 12 | R4: =100/Q4 -> 8.3333333
A5: 3 | B5: Claims | D5: =IF(F5>TODAY(),0%,NETWORKDAYS(F5,TODAY())*R5%) -> 0.2 | E5: 0% | F5: 46309 | G5: In Progress | H5: 46323 | I5: 46314 | J5: 46330 | K5: 46337 | L5: Ascendion | Q5: =NETWORKDAYS(F5,H5-1) -> 10 | R5: =100/Q5 -> 10
A6: 4 | B6: Digital | D6: =IF(F6>TODAY(),0%,NETWORKDAYS(F6,TODAY())*R6%) -> 0.38461538 | E6: 0.05 | F6: 46304 | G6: In Progress | H6: 46323 | I6: 46314 | J6: 46330 | K6: 46337 | L6: Ascendion | Q6: =NETWORKDAYS(F6,H6-1) -> 13 | R6: =100/Q6 -> 7.6923077
A7: 5 | B7: MyLife | D7: =IF(F7>TODAY(),0%,NETWORKDAYS(F7,TODAY())*R7%) -> 0.38461538 | E7: 0.05 | F7: 46304 | G7: In Progress | H7: 46323 | I7: 46314 | J7: 46330 | K7: 46337 | L7: Ascendion | Q7: =NETWORKDAYS(F7,H7-1) -> 13 | R7: =100/Q7 -> 7.6923077
A8: 6 | B8: Encounters | D8: =IF(F8>TODAY(),0%,NETWORKDAYS(F8,TODAY())*R8%) -> 0.38461538 | E8: 0.1 | F8: 46304 | G8: In Progress | H8: 46323 | I8: 46314 | J8: 46330 | K8: 46337 | L8: Ascendion | Q8: =NETWORKDAYS(F8,H8-1) -> 13 | R8: =100/Q8 -> 7.6923077
A9: 7 | B9: SAP Finance | C9: Red | D9: =IF(F9>TODAY(),0%,NETWORKDAYS(F9,TODAY())*R9%) -> 0 | E9: 0% | F9: 46314 | G9: In Progress | H9: 46323 | I9: 46323 | J9: 46330 | K9: 46337 | L9: Ascendion | Q9: =NETWORKDAYS(F9,H9-1) -> 7 | R9: =100/Q9 -> 14.285714
A10: 8 | B10: Clinical - UM/CM | D10: =IF(F10>TODAY(),0%,NETWORKDAYS(F10,TODAY())*R10%) -> 0.33333333 | E10: 0% | F10: 46307 | G10: In Progress | H10: 46323 | I10: 46314 | J10: 46330 | K10: 46337 | L10: Ascendion | Q10: =NETWORKDAYS(F10,H10-1) -> 12 | R10: =100/Q10 -> 8.3333333
A11: 9 | B11: CrossProduct | D11: =IF(F11>TODAY(),0%,NETWORKDAYS(F11,TODAY())*R11%) -> 0.33333333 | E11: 0% | F11: 46307 | G11: In Progress | H11: 46323 | I11: 46314 | J11: 46330 | K11: 46337 | L11: Ascendion | Q11: =NETWORKDAYS(F11,H11-1) -> 12 | R11: =100/Q11 -> 8.3333333
A12: 10 | B12: TDM | D12: =IF(F12>TODAY(),0%,NETWORKDAYS(F12,TODAY())*R12%) -> 0.38461538 | E12: 0.1 | F12: 46304 | G12: In Progress | H12: 46323 | I12: 46314 | J12: 46330 | K12: 46337 | L12: Ascendion | Q12: =NETWORKDAYS(F12,H12-1) -> 13 | R12: =100/Q12 -> 7.6923077
A13: 11 | B13: Platform Enablement TestingTools / Tools Admin | D13: =IF(F13>TODAY(),0%,NETWORKDAYS(F13,TODAY())*R13%) -> 0.33333333 | E13: 0% | F13: 46307 | G13: In Progress | H13: 46323 | I13: 46314 | J13: 46330 | K13: 46337 | L13: Ascendion | Q13: =NETWORKDAYS(F13,H13-1) -> 12 | R13: =100/Q13 -> 8.3333333
A14: 12 | B14: GenAI Build | D14: =IF(F14>TODAY(),0%,NETWORKDAYS(F14,TODAY())*R14%) -> 0.11111111 | E14: 0% | F14: 46310 | G14: Not Started | H14: 46323 | I14: 46314 | J14: 46330 | K14: 46337 | L14: Ascendion | Q14: =NETWORKDAYS(F14,H14-1) -> 9 | R14: =100/Q14 -> 11.111111
A16: 13 | B16: Clinical - Clin Auto | E16: - | F16: - | G16: - | H16: - | I16: - | J16: - | K16: - | L16: Ascendion
A17: 14 | B17: EDI | E17: - | F17: - | G17: - | H17: - | I17: - | J17: - | K17: - | L17: Ascendion
A18: 15 | B18: AI Testing | E18: - | F18: - | G18: - | H18: - | I18: - | J18: - | K18: - | L18: Ascendion
A20: 15 | B20: CXP | D20: =IF(F20>TODAY(),0%,NETWORKDAYS(F20,TODAY())*R20%) -> 0.11111111 | E20: 0% | F20: 46310 | G20: Not Started | H20: 46323 | I20: 46314 | J20: 46330 | K20: 46337 | L20: Infosys | Q20: =NETWORKDAYS(F20,H20-1) -> 9 | R20: =100/Q20 -> 11.111111

Sheet App & Wave Scope
A1: APP & WAVE SCOPE
A2: # | B2: Application | C2: Criticality | D2: High Touch | E2: Incumbent (Mentor anchor) | F2: Ascendion Mentee lead | G2: Onshore | H2: Offshore | I2: Single-person dep risk | J2: Backup mentee | K2: KT status
A3: 1 | B3: Enrollment | I3: Med | J3: TBD | K3: In Progress
A4: 2 | B4: Provider | I4: High | J4: TBD | K4: In Progress
A5: 3 | B5: Claims | I5: High | J5: TBD | K5: In Progress
A6: 4 | B6: Digital | I6: Med | J6: TBD | K6: In Progress
A7: 5 | B7: MyLife | I7: Med | J7: TBD | K7: In Progress
A8: 6 | B8: EDI | I8: Med | J8: TBD | K8: Not required
A9: 7 | B9: Encounters | I9: TBD | J9: TBD | K9: In Progress
A10: 8 | B10: SAP Finance | I10: TBD | J10: TBD | K10: Not started
A11: 9 | B11: Clinical - Clin Auto | I11: TBD | J11: TBD | K11: Not required
A12: 10 | B12: Clinical - UM/CM | I12: TBD | J12: TBD | K12: Not started (10/15)
A13: 11 | B13: CrossProduct | I13: TBD | J13: TBD | K13: In Progress
A14: 12 | B14: AI Testing | I14: TBD | J14: TBD | K14: Not required
... A17: 15 | B17: GenAI Build | I17: TBD | J17: TBD | K17: Not started

Sheet Transition - Progress by Domain
A1: KT SUMMARY STATUS
A2: # | B2: Application | C2: KT Start Date | D2: Understanding Doc | E2: Confidence level from QE Managers | F2: Confidence level from Qes | G2: KT Completion - Actual | H2: KT Completion - Planned | I2: Shadow | J2: Reverse-KT | K2: Reverse-Shadow | L2: Steady State | M2: Target vs Actuals | N2: Transition Effectiveness | O2: Steady-State Readiness | P2: Takeover-ready | Q2: Rolloff gate | R2: Target gate date
A3: 1 | B3: Enrollment | C3: 46307 | D3: In Progress | G3: 8 | I3: 46323 | J3: 46314 | K3: 46330 | L3: 46337 | N3: 0% | O3: 0% | P3: No | Q3: CLOSED
A4: 2 | B4: Provider | C4: 46307 | D4: In Progress | G4: 8 | I4: 46323 | J4: 46314 | K4: 46330 | L4: 46337 | N4: 0% | O4: 0% | P4: No | Q4: CLOSED
A5: 3 | B5: Claims | C5: 46309 | D5: In Progress | G5: 0% | I5: 46323 | J5: 46314 | K5: 46330 | L5: 46337 | N5: 0% | O5: 0% | P5: No | Q5: CLOSED
A6: 4 | B6: Digital | C6: 46304 | D6: In Progress | G6: 0.05 | I6: 46323 | J6: 46314 | K6: 46330 | L6: 46337 | N6: 0% | O6: 0% | P6: No | Q6: CLOSED
A7: 5 | B7: MyLife | C7: 46304 | D7: In Progress | G7: 0.05 | I7: 46323 | J7: 46314 | K7: 46330 | L7: 46337
A8: 6 | B8: EDI | C8: - | D8: - | G8: - | I8: - | J8: - | K8: - | L8: - | M8: - | N8: - | O8: - | P8: - | Q8: - | R8: -
A9: 7 | B9: Encounters | C9: 46304 | D9: In Progress | G9: 0.1 | I9: 46323 | J9: 46314 | K9: 46330 | L9: 46337 | N9: 0% | O9: 0% | P9: No | Q9: CLOSED
A10: 8 | B10: SAP Finance | C10: 46314 | D10: In Progress | G10: 0% | I10: 46328 | J10: 46323 | K10: 46330 | L10: 46337 | N10: 0% | O10: 0% | P10: No | Q10: CLOSED
A11: 9 | B11: Clinical - Clin Auto | C11: - | D11: - | G11: - | I11: - | J11: - | K11: - | L11: - | M11: - | N11: - | O11: - | P11: - | Q11: - | R11: -
A12: 10 | B12: Clinical - UM/CM | C12: 46307 | D12: In Progress | G12: 0% | I12: 46323 | J12: 46314 | K12: 46330 | L12: 46337 | N12: 0% | O12: 0% | P12: No | Q12: CLOSED
A13: 11 | B13: CrossProduct | C13: 46307 | D13: In Progress | G13: 0% | I13: 46323 | J13: 46314 | K13: 46330 | L13: 46337 | N13: 0% | O13: 0% | P13: No | Q13: CLOSED
A14: 12 | B14: AI Testing | C14: - | D14: - | G14: - | I14: - | J14: - | K14: - | L14: - | M14: - | N14: - | O14: - | P14: - | Q14: - | R14: -
A15: 13 | B15: TDM | C15: 46304 | D15: In Progress | G15: 0.1 | I15: 46323 | J15: 46314 | K15: 46330 | L15: 46337 | N15: 0% | O15: 0% | P15: No | Q15: CLOSED
A16: 14 | B16: Platform Enablement TestingTools / Tools Admin | C16: 46307 | D16: In Progress | G16: 0% | I16: 46323 | J16: 46314 | K16: 46330 | L16: 46337 | N16: 0% | O16: 0% | P16: No | Q16: CLOSED
A17: 14 | B17: GenAI Build | C17: 46310 | D17: Not Started | G17: 0% | I17: 46323 | J17: 46314 | K17: 46330 | L17: 46337 | N17: 0% | O17: 0% | P17: No | Q17: CLOSED

Sheet Team Roster
A1: Domain | B1: CareSource Manager | C1: ON LEAD | D1: DoJ | E1: OFF LEAD | F1: DoJ | G1: KT Readiness | H1: KT Plan
A2: Enrollment | B2: Christine | C2: Daniel* | D2: 46314 | E2: Screening in Progress | G2: Not Ready | H2: In Progress
A3: Provider | B3: Christine | C3: Kalai | D3: 46307 | E3: Rajasulochana | F3: 46301 | G3: Ready to Start | H3: In Progress
A4: Claims | B4: Jennifer | C4: Tanmay* | E4: Nithy | F4: 46301 | G4: Ready to Start
A5: SAP Finance | B5: Jennifer | C5: Kalyani* | E5: Screening in Progress
A6: Digital | B6: Sundar | C6: Sharath | D6: 46326 | E6: Sandheep Dhamle | F6: 46301 | G6: Starting Today | H6: Finalized
A7: MyLife | B7: Sundar | C7: Prasada lakshmi | D7: 46302 | E7: Sweta Singh | F7: 46301 | G7: Ready to Start | H7: In Progress
A8: EDI | B8: Suganya | C8: Jegadhish | D8: 46301 | E8: Alagu | F8: 46301 | G8: No KT needed | H8: NA
A9: Encounters | B9: Suganya | C9: Ritika Sethi* | E9: Dilli | F9: 46301 | G9: Ready to Start | H9: In Progress
A10: Clinical - Clin Auto | B10: Rommel | C10: Bhavani | D10: 46301 | E10: Selva | F10: 46301 | G10: No KT needed | H10: NA
A11: Clinical - UM | B11: Rommel | C11: Ata | E11: Swathi Kodumuru | F11: 46301 | G11: Ready to Start | H11: In Progress
A12: Clinical - CM | B12: Rommel | C12: Vidyulatha | D12: 46302
A13: SharedServices
A14: CrossProduct | B14: Rommel | C14: NA | E14: Mahesh Kumar | F14: 46301 | G14: Ready to Start | H14: In Progress
A15: AI Testing | B15: Sathish | C15: NA | E15: Radhika | F15: 46301 | G15: Ready to Start | H15: NA
A16: GenAI Team{Foundational Build) | B16: Sathish | C16: NA | E16: Screening in Progress
A17: TDM | B17: Sangeetha | C17: Ranjeeth | E17: Screening in Progress | G17: Ready to Start | H17: Finalized
A18: Platform Enablement TestingTools / Tools Admin | B18: Sangeetha | C18: NA | D18: 46301 | E18: Amit Verma/Srini | F18: 46307 | G18: In Progress | H18: Finalized
A19: QE Architect | B19: Sathish | E19: Mohan R
A20: QE SME | B20: Sathish | E20: Hariharan Krishnaraj
A22: AI Advisory | E22: Naveen Krishnamurthy
A23: Healthcare SME | E23: Illamathy En
A24: AI Lead | E24: Ansiya Thangal Kunju
A25: AI Builders | E25: Kruthika Ganesan / Sowmya Sridhar / Aaditya Nayar

Sheet Interview Tracking-Summary
A1: Domain / Area | B1: Onshore | C1: Offshore | D1: KT Readiness | J1: Domain / Area | K1: Onshore | L1: Offshore
A2: Provider | B2: Kalai Mani (10/12) | C2: Mani | J2: Provider
B3: Selected
B4: Screened (30-Sep)
A5: Enrollment | B5: Daniel Franklin | C5: Beula (Interview pending) | J5: Enrollment
B6: 🟢 Selected
B7: Interview Completed (29-Sep) ; Business Interview Completed on 30-Sep
A8: Claims | B8: Tanmaya | C8: Nithi | J8: Claims
B9: 🔴 Rejected
B10: Interview Completed (28-Sep)
A11: Encounter | B11: Mohammed Naeem 🔴 Rejected | C11: ⚪ | J11: Encounter
B12: Megala Kumar 🟡 Waitlist
B13: Dhanesh 🔵 Profile Under Review
A14: Clinical | B14: Megala Kumar 🔴 Rejected | C14: Swathi 🟢 Selected | J14: Clinical
B15: Vidhyulatha 🔴 Rejected
A16: Cross Product | B16: ⚪ | C16: Maheshkumar Reddy 🟢 Selected | J16: Cross Product
A17: Digital | B17: Danesh 🔴 Rejected | C17: ⚪ | J17: Digital
B18: Prasada Lakshmi 🔵 Profile Shared for Review
A19: PE | B19: Shiva Prasad 🔴 Rejected | C19: ⚪ | J19: PE
A20: TDM | B20: Ranjeeth | C20: Hrishikesh | J20: TDM

Sheet Interview Tracking
A1: CareSource Manager | B1: Domain | C1: Location | D1: Candidate | E1: Interview Date | F1: Process | G1: Decision
A2: Suganya Balaji | B2: Encounter QA Lead | C2: Onshore | D2: Megala Kumar | E2: 46288 | F2: Interview Completed | G2: Waitlist
A3: Jennifer Winders | B3: Claims Lead | C3: Onshore | D3: Tanmaya | E3: 46293 | F3: Interview Completed | G3: Rejected
A4: Rommel Tatel | B4: Clinical Lead | C4: Onshore | D4: Megala Kumar | E4: 46293 | F4: Interview Completed | G4: Rejected
A5: Rommel Tatel | B5: Clinical Lead | C5: Offshore | D5: Swathi | E5: 46293 | F5: Interview Completed | G5: Selected
A6: Rommel Tatel | B6: Cross Product Lead | C6: Offshore | D6: Maheshkumar Reddy | E6: 46293 | F6: Interview Completed | G6: Selected
A7: Suganya Balaji | B7: Encounter QA Lead | C7: Onshore | D7: Mohammed Naeem | E7: 46293 | F7: Interview Completed | G7: Rejected
A8: Sundar | B8: Digital | C8: Onshore | D8: Danesh | E8: 46293 | F8: Interview Completed | G8: Rejected
A9: Christine Huber | B9: Enrollment QA Lead | C9: Onshore | D9: Daniel Franklin | E9: 46294 | F9: Interview Completed | G9: Selected
A10: Christine Huber | B10: Provider QA Lead | C10: Onshore | D10: Kalai Mani | E10: 46295 | F10: Interview Completed | G10: Selected
A11: Rommel Tatel | B11: Clinical Lead | C11: Onshore | D11: Vidyulatha | E11: 46295 | F11: Interview Completed | G11: Rejected
A12: Sangeetha | B12: PE Lead | C12: Onshore | D12: Shiva Prasad | E12: 46296 | F12: Interview Completed | G12: Rejected
A13: Jennifer Winders | B13: Claims Lead | C13: Offshore | D13: Manasa | E13: 46297 | F13: Interview Completed | G13: Rejected
... A32: Christine Huber | B32: Provider Sr Tester | C32: Offshore | D32: Madhurima Paturu | E32: 46301 | F32: Interview Completed | G32: Selected
A33: Jennifer Winders | B33: Claims Sr Tester | C33: Offshore | D33: Saranya Koppuli | F33: Interview Completed | G33: Selected
A34: Christine Huber | B34: Enrollment Sr Tester | C34: Offshore | D34: Beula Evangelin | E34: 46302 | F34: Interview Completed | G34: Selected

Sheet Plan Summary
A1: EQE KT PLAN — CareSource
A2: Highlevel
A3: Stage | B3: What happens | D3: Exit evidence
A4: Plan | B4: Confirm mentor↔mentee, access, schedule, questionnaire issued | D4: Signed per-app KT schedule + access confirmed
A5: Knowledge Acquisition | B5: Incumbent-led sessions across 14 knowledge areas; draft Understanding Doc | D5: KA Coverage green; doc reviewed by CareSource
A6: Shadow | B6: Observe live testing/triage; incumbent still owns the work | D6: Shadow log, drafted SOPs, automation backlog, KM-gap list
A7: Reverse-KT / Reverse-Shadow | B7: Ascendion does the work and teaches it back; incumbent scores | D7: Transition Effectiveness ≥ 80%
A8: Stabilization | B8: Run day-to-day with on-call incumbent support only | D8: Steady-State Readiness ≥ 80%
A9: Steady-State | B9: Full ownership; incumbent rolls off this app | D9: Phase-gate sign-off + rolloff authorized
A11: Phase calendar
A12: Phase | B12: Window (dates from original - needs change) | C12: KT activity
A13: 0 — Pre-Planning | C13: Access/BGV in flight, mentors named, questionnaire issued to Incumbant
A14: 1 — Knowledge Acquisition | C14: KA across 14 areas; Understanding Docs drafted & reviewed
A15: 2 — Shadow / Reverse-Shadow | C15: shadow then reverse-KT; Transition Effectiveness scored
A16: 3 — Stabilization | C16: independent run; Steady-State Readiness scored; takeover & rolloff (gated)
A17: 4 — Steady-State | C17: BAU

Sheet KA Knowledge Areas
A1: KNOWLEDGE ACQUISITION — 14 AREAS × APP
A2: App | B2: # | C2: Knowledge area | D2: Est. hrs | E2: Mentor (Incumbant) | F2: Mentee (Ascendion) | G2: Planned start | H2: Planned end | I2: % complete | J2: Status | K2: Understanding doc? | L2: Comments
A3: ▸ Claims
A4: Claims | B4: 1 | C4: Application overview | D4: 1 | E4: TBD | F4: TBD | I4: 0 | J4: Pending | K4: No
A5: Claims | B5: 2 | C5: Solution architecture | D5: 1 | E5: TBD | F5: TBD | I5: 0 | J5: Pending | K5: No
A6: Claims | B6: 3 | C6: Functionality & features | D6: 8 | E6: TBD | F6: TBD | I6: 0 | J6: Pending | K6: No
A7: Claims | B7: 4 | C7: Upstream/downstream integration & environments | D7: 2.5 | E7: TBD | F7: TBD | I7: 0 | J7: Pending | K7: No
A8: Claims | B8: 5 | C8: Test strategy & master suite | D8: 4 | E8: TBD | F8: TBD | I8: 0 | J8: Pending | K8: No
A9: Claims | B9: 6 | C9: Regression suite | D9: 2 | E9: TBD | F9: TBD | I9: 0 | J9: Pending | K9: No
A10: Claims | B10: 7 | C10: Defect management (+ SLAs: S1 24h / S2 48h / S3 72h) | D10: 2 | E10: TBD | F10: TBD | I10: 0 | J10: Pending | K10: No
A11: Claims | B11: 8 | C11: Test data management | D11: 2 | E11: TBD | F11: TBD | I11: 0 | J11: Pending | K11: No
A12: Claims | B12: 9 | C12: Automation (framework, coverage, backlog) | D12: 4 | E12: TBD | F12: TBD | I12: 0 | J12: Pending | K12: No
A13: Claims | B13: 10 | C13: Recent projects (last 12 months) | D13: 4 | E13: TBD | F13: TBD | I13: 0 | J13: Pending | K13: No
A14: Claims | B14: 11 | C14: Inflight projects | D14: 2 | E14: TBD | F14: TBD | I14: 0 | J14: Pending | K14: No
A15: Claims | B15: 12 | C15: Peak / open-enrollment-specific testing | D15: 2 | E15: TBD | F15: TBD | I15: 0 | J15: Pending | K15: No
... A17: Claims | B17: 14 | C17: Business stakeholders | D17: 1 | E17: TBD | F17: TBD | I17: 0 | J17: Pending | K17: No
A18: ▸ Encounter
A19: Encounter | B19: 1 | C19: Application overview | D19: 1 | E19: TBD | F19: TBD | I19: 0 | J19: Pending | K19: No
A20: Encounter | B20: 2 | C20: Solution architecture | D20: 1 | E20: TBD | F20: TBD | I20: 0 | J20: Pending | K20: No
A21: Encounter | B21: 3 | C21: Functionality & features | D21: 8 | E21: TBD | F21: TBD | I21: 0 | J21: Pending | K21: No
A22: Encounter | B22: 4 | C22: Upstream/downstream integration & environments | D22: 2.5 | E22: TBD | F22: TBD | I22: 0 | J22: Pending | K22: No
A23: Encounter | B23: 5 | C23: Test strategy & master suite | D23: 4 | E23: TBD | F23: TBD | I23: 0 | J23: Pending | K23: No
A24: Encounter | B24: 6 | C24: Regression suite | D24: 2 | E24: TBD | F24: TBD | I24: 0 | J24: Pending | K24: No
A25: Encounter | B25: 7 | C25: Defect management (+ SLAs: S1 24h / S2 48h / S3 72h) | D25: 2 | E25: TBD | F25: TBD | I25: 0 | J25: Pending | K25: No
A26: Encounter | B26: 8 | C26: Test data management | D26: 2 | E26: TBD | F26: TBD | I26: 0 | J26: Pending | K26: No
A27: Encounter | B27: 9 | C27: Automation (framework, coverage, backlog) | D27: 4 | E27: TBD | F27: TBD | I27: 0 | J27: Pending | K27: No
A28: Encounter | B28: 10 | C28: Recent projects (last 12 months) | D28: 4 | E28: TBD | F28: TBD | I28: 0 | J28: Pending | K28: No
A29: Encounter | B29: 11 | C29: Inflight projects | D29: 2 | E29: TBD | F29: TBD | I29: 0 | J29: Pending | K29: No
A30: Encounter | B30: 12 | C30: Peak / open-enrollment-specific testing | D30: 2 | E30: TBD | F30: TBD | I30: 0 | J30: Pending | K30: No
... A32: Encounter | B32: 14 | C32: Business stakeholders | D32: 1 | E32: TBD | F32: TBD | I32: 0 | J32: Pending | K32: No
A33: ▸ Enrollment
A34: Enrollment | B34: 1 | C34: Application overview | D34: 1 | E34: TBD | F34: TBD | I34: 0 | J34: Pending | K34: No
A35: Enrollment | B35: 2 | C35: Solution architecture | D35: 1 | E35: TBD | F35: TBD | I35: 0 | J35: Pending | K35: No
A36: Enrollment | B36: 3 | C36: Functionality & features | D36: 8 | E36: TBD | F36: TBD | I36: 0 | J36: Pending | K36: No
A37: Enrollment | B37: 4 | C37: Upstream/downstream integration & environments | D37: 2.5 | E37: TBD | F37: TBD | I37: 0 | J37: Pending | K37: No
A38: Enrollment | B38: 5 | C38: Test strategy & master suite | D38: 4 | E38: TBD | F38: TBD | I38: 0 | J38: Pending | K38: No
A39: Enrollment | B39: 6 | C39: Regression suite | D39: 2 | E39: TBD | F39: TBD | I39: 0 | J39: Pending | K39: No
A40: Enrollment | B40: 7 | C40: Defect management (+ SLAs: S1 24h / S2 48h / S3 72h) | E40: TBD | F40: TBD | I40: 0 | J40: Pending | K40: No
A41: Enrollment | B41: 8 | C41: Test data management | D41: 2 | E41: TBD | F41: TBD | I41: 0 | J41: Pending | K41: No
A42: Enrollment | B42: 9 | C42: Automation (framework, coverage, backlog) | D42: 4 | E42: TBD | F42: TBD | I42: 0 | J42: Pending | K42: No
...

Sheet Discovery Questionnaire
A1: INCUMBENT DISCOVERY QUESTIONNAIRE
A2: # | B2: Category | C2: Question for incumbent | D2: Response | E2: Doc / link provided | F2: Follow-up
A3: 1 | B3: Release Management | C3: Provide the release calendar by domain/app (waterfall vs agile) and sprint timelines.
A4: 2 | B4: Release Management | C4: Who coordinates releases; what docs are provided per release cycle?
A5: 3 | B5: Release Management | C5: Are testers involved in prod cutover, checkout, warranty testing?
A6: 4 | B6: Release Management | C6: How are lessons-learnt / retrospectives captured per release/sprint?
A7: 5 | B7: Release Management | C7: Formal change/scope-management process during test execution?
A8: 6 | B8: Release Management | C8: Process for urgent break-fixes / e-fixes / ad-hoc releases (timeline)?
A9: 7 | B9: Environment & Data | C9: Enterprise environment strategy / path-to-production doc?
A10: 8 | B10: Environment & Data | C10: Test environments per test type (SIT, E2E, UAT)?
A11: 9 | B11: Environment & Data | C11: Recurring environment/infra challenges (access, refresh, downtime)?
A12: 10 | B12: Environment & Data | C12: Data-refresh activities in lower environments and their timing?
A13: 11 | B13: Environment & Data | C13: Access request model per environment / by role?
A14: 12 | B14: Environment & Data | C14: Pre-prod / prod (read-only) access rules for on/offshore?
... A39: 37 | B39: Deliverables | C39: Central repository for all deliverables — location?

Sheet KT Metrics & RAG
A1: KT METRICS & RAG
A2: # | B2: Metric | C2: Formula | D2: What it tells us | E2: Green | F2: Amber | G2: Red | H2: Role | I2: Planned | J2: Actual | K2: Health
A3: 1 | B3: KA Session Coverage | C3: KA sessions held / planned | D3: Coverage of incumbent-led KA vs plan | E3: 97–103% | F3: 90–<97% or 103–110% | G3: <90% or >110% | H3: Leading | I3: 100% | J3: 0% | K3: N/A
A4: 2 | B4: SME Effort Utilization | C4: Actual / planned mentor effort | D4: Incumbent SME time actually spent vs committed | E4: 90–110% | F4: 70–<90% or 110–120% | G4: <70% or >120% | H4: Leading | I4: 100% | J4: 0% | K4: N/A
A5: 3 | B5: Transition Effectiveness | C5: Weighted reverse-KT + stage-gate feedback score | D5: Quality of knowledge absorbed (scored by incumbent+client) | E5: ≥80% | F5: 60–<80% | G5: <60% | H5: GATE | I5: 100% | J5: 0% | K5: N/A
A6: 4 | B6: KT Documentation Efficiency | C6: Mandatory docs delivered / planned | D6: Understanding docs, SOPs, runbooks received | E6: 100% | F6: 90–<100% | G6: <90% | H6: Leading | I6: 100% | J6: 0% | K6: N/A
A7: 5 | B7: KT Schedule Adherence | C7: Actual / planned progress | D7: On-track vs the dated KA/shadow plan | E7: 95–105% | F7: 85–<95% or 105–115% | G7: <85% or >115% | H7: Leading | I7: 100% | J7: 0% | K7: N/A
A8: 6 | B8: KV (Reverse-KT) Session Coverage | C8: KV sessions held / planned | D8: Coverage of teach-back/reverse-KT vs plan | E8: 97–103% | F8: 90–<97% or 103–110% | G8: <90% or >110% | H8: Leading | I8: 100% | J8: 0% | K8: N/A
A9: 7 | B9: Steady-State Readiness | C9: Tasks done independently / total tasks | D9: Ability to run BAU without mentor support | E9: ≥80% | F9: 70–<80% | G9: <70% | H9: GATE | I9: 100% | J9: 0% | K9: N/A
A10: 8 | B10: AI Agent readiness ?? | D10: How ready are the agents from context?

Sheet Phase Gates
A1: PHASE GATES
A2: Phase | B2: Exit criterion (binary) | C2: Met? (Y/N) | D2: Evidence / metric | E2: Sign-off — CareSource | F2: Sign-off — Ascendion | G2: Date
A3: 0 Pre-Planning | B3: Named Incumbant mentor + confirmed access for each app | C3: N
A4: 0 Pre-Planning | B4: Discovery questionnaire issued to incumbent | C4: N
A5: 1 KA | B5: Understanding Doc drafted & reviewed by CareSource | C5: N
A6: 1 KA | B6: KA Session Coverage green (≥97%) | C6: N
A7: 2 Shadow/Reverse | B7: Shadow log + SOPs/runbooks + automation backlog delivered | C7: N
A8: 2 Shadow/Reverse | B8: Transition Effectiveness ≥ 80% | C8: N
A9: 3 Stabilization | B9: Steady-State Readiness ≥ 80% | C9: N
A10: 3 Stabilization | B10: Rolloff authorized — incumbent exits this app | C10: N
A11: 4 Steady-State | B11: BAU stable; Wave-2 KA started | C11: N

Sheet Access & Onboarding
A1: ACCESS & ONBOARDING FUNNEL
A2: # | B2: Name | C2: Pod / App | D2: Onshore/Offshore | E2: BGV clear | F2: CareSource ID | G2: VM / laptop login | H2: Tool access level | I2: App groups | J2: Ready for KT? | K2: Comments
A3: 1 | E3: No | G3: No | H3: L1 | J3: No
A4: 2 | E4: No | G4: No | H4: L1 | J4: No
A5: 3 | E5: No | G5: No | H5: L1 | J5: No
A6: 4 | E6: No | G6: No | H6: L1 | J6: No
A7: 5 | E7: No | G7: No | H7: L1 | J7: No
A8: 6 | E8: No | G8: No | H8: L1 | J8: No
A9: 7 | E9: No | G9: No | H9: L1 | J9: No
A10: 8 | E10: No | G10: No | H10: L1 | J10: No
A11: 9 | E11: No | G11: No | H11: L1 | J11: No
A12: 10 | E12: No | G12: No | H12: L1 | J12: No
A13: 11 | E13: No | G13: No | H13: L1 | J13: No
A14: 12 | E14: No | G14: No | H14: L1 | J14: No
... A22: 20 | E22: No | G22: No | H22: L1 | J22: No

Sheet Governance & Cadence
A1: GOVERNANCE & CADENCE
A2: Daily → weekly → phase-gate → monthly/quarterly · feeds Leadership/04_Weekly_Leadership_Governance_Pack.xlsx
A4: Cadence | B4: Ritual | C4: Content | D4: Owner | E4: Audience | F4: Distribution
A5: Daily | B5: Pod DSR | C5: KA/shadow progress, blockers, no-show escalations | D5: Pod lead | E5: Ascendion + CareSource app owners | F5: Email EOD
A6: Weekly | B6: KT status pack | C6: Per-app: KA% · Reverse-KT% · Transition Effectiveness · Steady-State Readiness · rolloff-gate · risks | D6: EQE Delivery Lead | E6: CareSource steering | F6: Deck, weekly
A7: Per gate | B7: Phase-gate review | C7: Binary exit criteria sign-off per app | D7: Delivery Lead + CareSource owner | E7: Joint | F7: Signed gate sheet
A8: Monthly | B8: Service review | C8: Metrics trend, doc efficiency, Wave-2 readiness | D8: Delivery Lead | E8: CareSource + Ascendion mgmt | F8: Deck
A9: Quarterly | B9: Steering committee | C9: Strategic view, AAVA/AI adoption, next-quarter plan | D9: Delivery Head | E9: Sponsors | F9: Deck

Sheet KT RAID
A1: KT RAID LOG
A2: KT-specific risks · assumptions · issues · decisions
A4: # | B4: Type | C4: App / scope | D4: Description | E4: Category | F4: Owner | G4: Raised | H4: Due | I4: Status | J4: Mitigation / decision
A5: 1 | B5: Risk | C5: All | D5: Incumbent (Incumbant) SME availability/goodwill during takeover | E5: Risk | F5: EQE Delivery Lead | H5: Ongoing | I5: Open | J5: Named mentors + committed hours in writing; daily no-show escalation
A6: 2 | B6: Risk | C6: Enrollment/Provider/MyLife/Encounter | D6: Peak/open-enrollment exposure | E6: Risk | F6: EQE Delivery Lead | H6: Ongoing | I6: Open | J6: Peak carve-out + incumbent billable-on-standby through 1st peak intake

Sheet POCs Client
B1: DELIVERY & Governance POCs
B2: App1 | C2: Client Reporting Manager | D2: Incumbent Vendor Contact | E2: Incumbent Vendor Lead | F2: CareSource SME
B3: Name
B4: E-mail
B5: App2 | C5: Client Reporting Manager | D5: Incumbent Vendor Contact | E5: Incumbent Vendor Lead | F5: CareSource SME
B6: Name
B7: E-mail
B8: App3 | C8: Client Reporting Manager | D8: Incumbent Vendor Contact | E8: Incumbent Vendor Lead | F8: CareSource SME
B9: Name
B10: E-mail

Sheet POCs Ascendion
B2: DELIVERY POCs & ESCALATION POINTS
B3: Ascendion
B4: All Towers | C4: Primary | D4: Service Operation Manager | E4: Delivery Head
B5: Name
B6: Mobile
B7: Work phone
B8: CareSource E-mail
B9: Ascendion E-mail

Sheet PivotCandidate
A3: Row Labels | B3: Count of Status
A4: Existing | B4: 24
A5: Onboarding in Progress | B5: 10
A6: Ascendion Pipeline | B6: 13
A7: KT Ready | B7: 42
A8: Login ID Issues | B8: 3
A9: Interview Selected | B9: 1
A10: Identifying | B10: 2
A11: Grand Total | B11: 95

Sheet Focus Areas
B1: Focus | C1: Status
A2: 1 | B2: Candidate profiles by product area
A3: =A2+1 -> 2 | B3: Interview and onboarding plan
A4: =A3+1 -> 3 | B4: End-to-end transition plan
A5: =A4+1 -> 4 | B5: Knowledge-transfer preparation
A6: =A5+1 -> 5 | B6: Near-term staffing coverage
A7: =A6+1 -> 6 | B7: Contract and SOW
A8: =A7+1 -> 7 | B8: Live transition dashboard
B10: ADO to track stories - Ascendion will manage
B12: Product-area workload and staffing

Sheet First KT Update
A1: Action Item | B1: Status | C1: Pending
A2: Candidate profiles by product area | B2: Candidate profiles shared with respective domain QE Managers by product area; currently under review. | C2: SAP Finance, Tools Admin
A3: Interview and onboarding plan | B3: In discussion with domain QE Managers; scheduling in progress. Meeting invites to be sent by EOD Friday.
A4: End-to-end transition plan | B4: Transition plan shared in Excel format
B5: Next step: translate into a live dashboard.
A6: Live Transition Dashboard | B6: Live dashboard to be built in Power BI (Ascendion environment) for on-demand visibility to CareSource management. WIP version available for preview tomorrow; target completion 9/28. A static HTML version will be shared first for feedback before finalizing.
B8: Dependency on CareSource: support needed to host the source file in the CareSource environment
A9: Knowledge-transfer preparation | B9: a) Accelerated Bootcamp (pre-KT readiness) - Identified talent going through an accelerated bootcamp training as listed below
B10: Orientation: Engagement overview, EQE goals, roles & responsibilities
B11: Training: Healthcare domain + Playwright refresher sessions
B12: Mentorship: SME assigned per domain for tools/process onboarding (ADO, qTest, Confluence, timesheets, access requests, AVD)
B13: Knowledge and experience sharing sessions from current domain Leads
B14: Periodic progress check-ins on KT readiness
B16: b) AI-Assisted KT Enablement
B17: Team mobilized to drive the KT process with Self Learning as focus
B18: Named individuals identified and assigned to lead this effort, names shared with Individual Managers
B20: c) AI-Assisted KT Assets
B21: Knowledge agent vectorization + retrieval pipeline (Contextualization layer being built) - indexing GitHub repos and SharePoint documents into a searchable knowledge base
B22: Chatbot solution being built on top of the indexed knowledge base for on-demand Q&A
B23: Auto-generated documentation from the indexed content, in progress
... B28: CareSource dependency: AAVA Contextualization service needs to be deployed in the CareSource environment (additional containers required); M365 Copilot license needed for the KT duration
A29: Near-term staffing coverage | B29: Key named individuals for Transition initiation across onshore and offshore shared
B30: Onboarding and pre-KT for QEs will proceed in waves between Oct 1 and Nov 13, with week-on-week progress updates
A31: Contract and SOW | B31: Base SOW is being drafted by CareSource (Amanda); once received, Ascendion will review and finalize.
